<mujoco model="humanoid_soccer">
  <!-- 
    人形機器人足球場景
    基於 Gymnasium Humanoid-v5 修改，加入足球和球門
  -->
  
  <compiler angle="degree" inertiafromgeom="true"/>
  
  <default>
    <joint armature="1" damping="1" limited="true"/>
    <geom conaffinity="1" condim="3" contype="1" margin="0.001" material="geom" rgba="0.8 0.6 .4 1"/>
    <motor ctrllimited="true" ctrlrange="-.4 .4"/>
  </default>
  
  <option integrator="RK4" iterations="50" solver="PGS" timestep="0.003"/>
  
  <size nkey="5" nuser_geom="1"/>
  
  <visual>
    <map fogend="5" fogstart="3"/>
    <global offwidth="1280" offheight="720"/>
  </visual>
  
  <asset>
    <texture builtin="gradient" height="100" rgb1=".4 .5 .6" rgb2="0 0 0" type="skybox" width="100"/>
    <texture builtin="flat" height="1278" mark="cross" markrgb="1 1 1" name="texgeom" random="0.01" rgb1="0.8 0.6 0.4" rgb2="0.8 0.6 0.4" type="cube" width="127"/>
    <texture builtin="checker" height="100" name="texplane" rgb1="0.2 0.6 0.2" rgb2="0.1 0.5 0.1" type="2d" width="100"/>
    <material name="MatPlane" reflectance="0.5" shininess="1" specular="1" texrepeat="30 30" texture="texplane"/>
    <material name="geom" texture="texgeom" texuniform="true"/>
    <!-- 足球材質 - 白色帶黑色斑紋 -->
    <material name="ball_material" rgba="1 1 1 1" specular="0.5" shininess="0.5"/>
    <!-- 球門材質 - 白色 -->
    <material name="goal_material" rgba="1 1 1 1"/>
  </asset>
  
  <worldbody>
    <!-- 光源 -->
    <light cutoff="100" diffuse="1 1 1" dir="-0 0 -1.3" directional="true" exponent="1" pos="0 0 1.3" specular=".1 .1 .1"/>
    
    <!-- 地板 - 綠色足球場 -->
    <geom conaffinity="1" condim="3" material="MatPlane" name="floor" pos="0 0 0" rgba="0.2 0.6 0.2 1" size="20 20 0.1" type="plane"/>
    
    <!-- ==================== 人形機器人 ==================== -->
    <body name="torso" pos="0 0 1.4">
      <camera name="track" mode="trackcom" pos="0 -4 0" xyaxes="1 0 0 0 0 1"/>
      <joint armature="0" damping="0" limited="false" name="root" pos="0 0 0" stiffness="0" type="free"/>
      <geom fromto="0 -.07 0 0 .07 0" name="torso1" size="0.07" type="capsule"/>
      <geom name="head" pos="0 0 .19" size=".09" type="sphere" user="258"/>
      <geom fromto="-.01 -.06 -.12 -.01 .06 -.12" name="uwaist" size="0.06" type="capsule"/>
      
      <body name="lwaist" pos="-.01 0 -0.260" quat="1.000 0 -0.002 0">
        <geom fromto="0 -.06 0 0 .06 0" name="lwaist" size="0.06" type="capsule"/>
        <joint armature="0.02" axis="0 0 1" damping="5" name="abdomen_z" pos="0 0 0.065" range="-45 45" stiffness="20" type="hinge"/>
        <joint armature="0.02" axis="0 1 0" damping="5" name="abdomen_y" pos="0 0 0.065" range="-75 30" stiffness="10" type="hinge"/>
        
        <body name="pelvis" pos="0 0 -0.165" quat="1.000 0 -0.002 0">
          <joint armature="0.02" axis="1 0 0" damping="5" name="abdomen_x" pos="0 0 0.1" range="-35 35" stiffness="10" type="hinge"/>
          <geom fromto="-.02 -.07 0 -.02 .07 0" name="butt" size="0.09" type="capsule"/>
          
          <!-- 右腿 -->
          <body name="right_thigh" pos="0 -0.1 -0.04">
            <joint armature="0.01" axis="-1 0 0" damping="5" name="right_hip_x" pos="0 0 0" range="-25 5" stiffness="10" type="hinge"/>
            <joint armature="0.01" axis="0 0 -1" damping="5" name="right_hip_z" pos="0 0 0" range="-60 35" stiffness="10" type="hinge"/>
            <joint armature="0.0080" axis="0 1 0" damping="5" name="right_hip_y" pos="0 0 0" range="-110 20" stiffness="20" type="hinge"/>
            <geom fromto="0 0 0 0 0.01 -.34" name="right_thigh1" size="0.06" type="capsule"/>
            
            <body name="right_shin" pos="0 0.01 -0.403">
              <joint armature="0.0060" axis="0 -1 0" name="right_knee" pos="0 0 .02" range="-160 -2" stiffness="1" type="hinge"/>
              <geom fromto="0 0 0 0 0 -.3" name="right_shin1" size="0.049" type="capsule"/>
              
              <body name="right_foot" pos="0 0 -0.35">
                <joint armature="0.0008" axis="0 1 0" name="right_ankle_y" pos="0 0 0.08" range="-50 50" stiffness="4" type="hinge"/>
                <joint armature="0.0006" axis="1 0 0.5" name="right_ankle_x" pos="0 0 0.08" range="-50 50" stiffness="1" type="hinge"/>
                <geom name="right_foot" type="sphere" size="0.075" pos="0 0 0.1" user="0" />
              </body>
            </body>
          </body>
          
          <!-- 左腿 -->
          <body name="left_thigh" pos="0 0.1 -0.04">
            <joint armature="0.01" axis="-1 0 0" damping="5" name="left_hip_x" pos="0 0 0" range="-25 5" stiffness="10" type="hinge"/>
            <joint armature="0.01" axis="0 0 -1" damping="5" name="left_hip_z" pos="0 0 0" range="-60 35" stiffness="10" type="hinge"/>
            <joint armature="0.01" axis="0 1 0" damping="5" name="left_hip_y" pos="0 0 0" range="-110 20" stiffness="20" type="hinge"/>
            <geom fromto="0 0 0 0 -0.01 -.34" name="left_thigh1" size="0.06" type="capsule"/>
            
            <body name="left_shin" pos="0 -0.01 -0.403">
              <joint armature="0.0060" axis="0 -1 0" name="left_knee" pos="0 0 .02" range="-160 -2" stiffness="1" type="hinge"/>
              <geom fromto="0 0 0 0 0 -.3" name="left_shin1" size="0.049" type="capsule"/>
              
              <body name="left_foot" pos="0 0 -0.35">
                <joint armature="0.0008" axis="0 1 0" name="left_ankle_y" pos="0 0 0.08" range="-50 50" stiffness="4" type="hinge"/>
                <joint armature="0.0006" axis="1 0 0.5" name="left_ankle_x" pos="0 0 0.08" range="-50 50" stiffness="1" type="hinge"/>
                <geom name="left_foot" type="sphere" size="0.075" pos="0 0 0.1" user="0" />
              </body>
            </body>
          </body>
        </body>
      </body>
      
      <!-- 右臂 -->
      <body name="right_upper_arm" pos="0 -0.17 0.06">
        <joint armature="0.0068" axis="2 1 1" name="right_shoulder1" pos="0 0 0" range="-85 60" stiffness="1" type="hinge"/>
        <joint armature="0.0051" axis="0 -1 1" name="right_shoulder2" pos="0 0 0" range="-85 60" stiffness="1" type="hinge"/>
        <geom fromto="0 0 0 .16 -.16 -.16" name="right_uarm1" size="0.04 0.16" type="capsule"/>
        
        <body name="right_lower_arm" pos=".18 -.18 -.18">
          <joint armature="0.0028" axis="0 -1 1" name="right_elbow" pos="0 0 0" range="-90 50" stiffness="0" type="hinge"/>
          <geom fromto="0.01 0.01 0.01 .17 .17 .17" name="right_larm" size="0.031" type="capsule"/>
          <geom name="right_hand" pos=".18 .18 .18" size="0.04" type="sphere"/>
        </body>
      </body>
      
      <!-- 左臂 -->
      <body name="left_upper_arm" pos="0 0.17 0.06">
        <joint armature="0.0068" axis="2 -1 1" name="left_shoulder1" pos="0 0 0" range="-60 85" stiffness="1" type="hinge"/>
        <joint armature="0.0051" axis="0 1 1" name="left_shoulder2" pos="0 0 0" range="-60 85" stiffness="1" type="hinge"/>
        <geom fromto="0 0 0 .16 .16 -.16" name="left_uarm1" size="0.04 0.16" type="capsule"/>
        
        <body name="left_lower_arm" pos=".18 .18 -.18">
          <joint armature="0.0028" axis="0 -1 -1" name="left_elbow" pos="0 0 0" range="-90 50" stiffness="0" type="hinge"/>
          <geom fromto="0.01 -0.01 0.01 .17 -.17 .17" name="left_larm" size="0.031" type="capsule"/>
          <geom name="left_hand" pos=".18 -.18 .18" size="0.04" type="sphere"/>
        </body>
      </body>
    </body>
    
    <!-- ==================== 足球 ==================== -->
    <!-- 
      球放在機器人前方 1.5 公尺處
      使用 freejoint 讓球可以自由移動
      半徑 0.11 公尺（標準足球約 22cm 直徑）
    -->
    <body name="ball" pos="1.5 0 0.11">
      <joint name="ball_joint" type="free" armature="0" damping="0.01"/>
      <geom name="ball_geom" type="sphere" size="0.11" mass="0.43" 
            material="ball_material" rgba="1 1 1 1"
            contype="1" conaffinity="1" condim="3"
            friction="0.7 0.005 0.0001"/>
    </body>
    
    <!-- ==================== 球門 ==================== -->
    <!-- 
      球門在機器人前方 5 公尺處
      標準五人制球門約 3m x 2m，這裡簡化為 2m x 1m
    -->
    <!-- 球門左柱 -->
    <geom name="goal_post_left" type="cylinder" size="0.05 0.5" 
          pos="5 -1 0.5" rgba="1 1 1 1" contype="1" conaffinity="1"/>
    <!-- 球門右柱 -->
    <geom name="goal_post_right" type="cylinder" size="0.05 0.5" 
          pos="5 1 0.5" rgba="1 1 1 1" contype="1" conaffinity="1"/>
    <!-- 球門橫樑 -->
    <geom name="goal_crossbar" type="cylinder" size="0.05 1" 
          pos="5 0 1" euler="90 0 0" rgba="1 1 1 1" contype="1" conaffinity="1"/>
    
    <!-- 球門偵測區域（透明，用於判斷進球） -->
    <site name="goal_zone" type="box" size="0.1 1 0.5" pos="5.1 0 0.5" rgba="1 0 0 0.1"/>
    
  </worldbody>
  
  <!-- ==================== 執行器（馬達） ==================== -->
  <actuator>
    <motor ctrllimited="true" ctrlrange="-.4 .4" joint="abdomen_y" gear="40"/>
    <motor ctrllimited="true" ctrlrange="-.4 .4" joint="abdomen_z" gear="40"/>
    <motor ctrllimited="true" ctrlrange="-.4 .4" joint="abdomen_x" gear="40"/>
    <motor ctrllimited="true" ctrlrange="-.4 .4" joint="right_hip_x" gear="40"/>
    <motor ctrllimited="true" ctrlrange="-.4 .4" joint="right_hip_z" gear="40"/>
    <motor ctrllimited="true" ctrlrange="-.4 .4" joint="right_hip_y" gear="120"/>
    <motor ctrllimited="true" ctrlrange="-.4 .4" joint="right_knee" gear="80"/>
    <motor ctrllimited="true" ctrlrange="-.4 .4" joint="right_ankle_y" gear="20"/>
    <motor ctrllimited="true" ctrlrange="-.4 .4" joint="right_ankle_x" gear="20"/>
    <motor ctrllimited="true" ctrlrange="-.4 .4" joint="left_hip_x" gear="40"/>
    <motor ctrllimited="true" ctrlrange="-.4 .4" joint="left_hip_z" gear="40"/>
    <motor ctrllimited="true" ctrlrange="-.4 .4" joint="left_hip_y" gear="120"/>
    <motor ctrllimited="true" ctrlrange="-.4 .4" joint="left_knee" gear="80"/>
    <motor ctrllimited="true" ctrlrange="-.4 .4" joint="left_ankle_y" gear="20"/>
    <motor ctrllimited="true" ctrlrange="-.4 .4" joint="left_ankle_x" gear="20"/>
    <motor ctrllimited="true" ctrlrange="-.4 .4" joint="right_shoulder1" gear="20"/>
    <motor ctrllimited="true" ctrlrange="-.4 .4" joint="right_shoulder2" gear="20"/>
    <motor ctrllimited="true" ctrlrange="-.4 .4" joint="right_elbow" gear="40"/>
    <motor ctrllimited="true" ctrlrange="-.4 .4" joint="left_shoulder1" gear="20"/>
    <motor ctrllimited="true" ctrlrange="-.4 .4" joint="left_shoulder2" gear="20"/>
    <motor ctrllimited="true" ctrlrange="-.4 .4" joint="left_elbow" gear="40"/>
  </actuator>
  
</mujoco>